ERROR:root:Error: Failed to play song: Already connected to a voice channel.
ERROR:discord.client:Attempting a reconnect in 1.22s
Traceback (most recent call last):
  File "D:\Projects\Kennapi\.venv\lib\site-packages\aiohttp\connector.py", line 999, in _create_direct_connection
    hosts = await asyncio.shield(host_resolved)
  File "D:\Projects\Kennapi\.venv\lib\site-packages\aiohttp\connector.py", line 865, in _resolve_host
    addrs = await self._resolver.resolve(host, port, family=self._family)
  File "D:\Projects\Kennapi\.venv\lib\site-packages\aiohttp\resolver.py", line 31, in resolve
    infos = await self._loop.getaddrinfo(
  File "C:\Program Files\WindowsApps\PythonSoftwareFoundation.Python.3.10_3.10.3056.0_x64__qbz5n2kfra8p0\lib\asyncio\base_events.py", line 863, in getaddrinfo
    return await self.run_in_executor(
  File "C:\Program Files\WindowsApps\PythonSoftwareFoundation.Python.3.10_3.10.3056.0_x64__qbz5n2kfra8p0\lib\concurrent\futures\thread.py", line 58, in run
    result = self.fn(*self.args, **self.kwargs)
  File "C:\Program Files\WindowsApps\PythonSoftwareFoundation.Python.3.10_3.10.3056.0_x64__qbz5n2kfra8p0\lib\socket.py", line 955, in getaddrinfo
    for res in _socket.getaddrinfo(host, port, family, type, proto, flags):
socket.gaierror: [Errno 11001] getaddrinfo failed

The above exception was the direct cause of the following exception:

Traceback (most recent call last):
  File "D:\Projects\Kennapi\.venv\lib\site-packages\discord\client.py", line 563, in connect
    self.ws = await asyncio.wait_for(coro, timeout=60.0)
  File "C:\Program Files\WindowsApps\PythonSoftwareFoundation.Python.3.10_3.10.3056.0_x64__qbz5n2kfra8p0\lib\asyncio\tasks.py", line 445, in wait_for
    return fut.result()
  File "D:\Projects\Kennapi\.venv\lib\site-packages\discord\gateway.py", line 305, in from_client
    gateway = gateway or await client.http.get_gateway()
  File "D:\Projects\Kennapi\.venv\lib\site-packages\discord\http.py", line 967, in get_gateway
    data = await self.request(Route('GET', '/gateway'))
  File "D:\Projects\Kennapi\.venv\lib\site-packages\discord\http.py", line 192, in request
    async with self.__session.request(method, url, **kwargs) as r:
  File "D:\Projects\Kennapi\.venv\lib\site-packages\aiohttp\client.py", line 1117, in __aenter__
    self._resp = await self._coro
  File "D:\Projects\Kennapi\.venv\lib\site-packages\aiohttp\client.py", line 520, in _request
    conn = await self._connector.connect(
  File "D:\Projects\Kennapi\.venv\lib\site-packages\aiohttp\connector.py", line 535, in connect
    proto = await self._create_connection(req, traces, timeout)
  File "D:\Projects\Kennapi\.venv\lib\site-packages\aiohttp\connector.py", line 892, in _create_connection
    _, proto = await self._create_direct_connection(req, traces, timeout)
  File "D:\Projects\Kennapi\.venv\lib\site-packages\aiohttp\connector.py", line 1011, in _create_direct_connection
    raise ClientConnectorError(req.connection_key, exc) from exc
aiohttp.client_exceptions.ClientConnectorError: Cannot connect to host discord.com:443 ssl:default [getaddrinfo failed]
ERROR:root:Error: Failed to play song: Already connected to a voice channel.
